<?xml version="1.0"?>
<robot name="humanoid_with_joints">
  <!-- Torso -->
  <link name="torso">
    <visual>
      <geometry>
        <box size="0.3 0.2 0.5"/>
      </geometry>
      <material name="light_grey">
        <color rgba="0.7 0.7 0.7 1"/>
      </material>
    </visual>
    <collision>
      <geometry>
        <box size="0.3 0.2 0.5"/>
      </geometry>
    </collision>
    <inertial>
      <mass value="5"/>
      <inertia ixx="0.1" ixy="0" ixz="0" iyy="0.1" iyz="0" izz="0.1"/>
    </inertial>
  </link>

  <!-- Right Arm -->
  <link name="right_upper_arm">
    <visual>
      <geometry>
        <cylinder radius="0.05" length="0.3"/>
      </geometry>
      <material name="arm_color">
        <color rgba="0.8 0.8 0.8 1"/>
      </material>
    </visual>
    <collision>
      <geometry>
        <cylinder radius="0.05" length="0.3"/>
      </geometry>
    </collision>
    <inertial>
      <mass value="0.5"/>
      <inertia ixx="0.005" ixy="0" ixz="0" iyy="0.005" iyz="0" izz="0.0005"/>
    </inertial>
  </link>

  <!-- Left Arm -->
  <link name="left_upper_arm">
    <visual>
      <geometry>
        <cylinder radius="0.05" length="0.3"/>
      </geometry>
      <material name="arm_color">
        <color rgba="0.8 0.8 0.8 1"/>
      </material>
    </visual>
    <collision>
      <geometry>
        <cylinder radius="0.05" length="0.3"/>
      </geometry>
    </collision>
    <inertial>
      <mass value="0.5"/>
      <inertia ixx="0.005" ixy="0" ixz="0" iyy="0.005" iyz="0" izz="0.0005"/>
    </inertial>
  </link>

  <!-- Right Leg -->
  <link name="right_upper_leg">
    <visual>
      <geometry>
        <cylinder radius="0.06" length="0.4"/>
      </geometry>
      <material name="leg_color">
        <color rgba="0.6 0.6 0.6 1"/>
      </material>
    </visual>
    <collision>
      <geometry>
        <cylinder radius="0.06" length="0.4"/>
      </geometry>
    </collision>
    <inertial>
      <mass value="0.8"/>
      <inertia ixx="0.01" ixy="0" ixz="0" iyy="0.01" iyz="0" izz="0.001"/>
    </inertial>
  </link>

  <!-- Left Leg -->
  <link name="left_upper_leg">
    <visual>
      <geometry>
        <cylinder radius="0.06" length="0.4"/>
      </geometry>
      <material name="leg_color">
        <color rgba="0.6 0.6 0.6 1"/>
      </material>
    </visual>
    <collision>
      <geometry>
        <cylinder radius="0.06" length="0.4"/>
      </geometry>
    </collision>
    <inertial>
      <mass value="0.8"/>
      <inertia ixx="0.01" ixy="0" ixz="0" iyy="0.01" iyz="0" izz="0.001"/>
    </inertial>
  </link>

  <!-- Joint connecting torso and right arm -->
  <joint name="right_shoulder_joint" type="revolute">
    <parent link="torso"/>
    <child link="right_upper_arm"/>
    <origin xyz="-0.15 0 0.1" rpy="0 0 0"/>
    <axis xyz="0 1 0"/>
    <limit lower="-1.57" upper="1.57" effort="100" velocity="1"/>
  </joint>

  <!-- Joint connecting torso and left arm -->
  <joint name="left_shoulder_joint" type="revolute">
    <parent link="torso"/>
    <child link="left_upper_arm"/>
    <origin xyz="0.15 0 0.1" rpy="0 0 0"/>
    <axis xyz="0 1 0"/>
    <limit lower="-1.57" upper="1.57" effort="100" velocity="1"/>
  </joint>

  <!-- Joint connecting torso and right leg -->
  <joint name="right_hip_joint" type="revolute">
    <parent link="torso"/>
    <child link="right_upper_leg"/>
    <origin xyz="-0.08 -0.05 -0.25" rpy="0 0 0"/>
    <axis xyz="0 1 0"/>
    <limit lower="-1.57" upper="1.57" effort="100" velocity="1"/>
  </joint>

  <!-- Joint connecting torso and left leg -->
  <joint name="left_hip_joint" type="revolute">
    <parent link="torso"/>
    <child link="left_upper_leg"/>
    <origin xyz="0.08 -0.05 -0.25" rpy="0 0 0"/>
    <axis xyz="0 1 0"/>
    <limit lower="-1.57" upper="1.57" effort="100" velocity="1"/>
  </joint>
</robot>